Traceback (most recent call last):
  File "/lihao/2023_AAI_Project_Unsteable_hand_writing_-Digit-Recognitionle/src/main.py", line 63, in <module>
    train1()
  File "/lihao/2023_AAI_Project_Unsteable_hand_writing_-Digit-Recognitionle/src/main.py", line 35, in train1
    draw_loss(losses, title=name+'_loss')
  File "/lihao/2023_AAI_Project_Unsteable_hand_writing_-Digit-Recognitionle/src/utils.py", line 85, in draw_loss
    plt.savefig('./pic/'+title+'.png')
  File "/root/miniconda3/envs/torch2/lib/python3.10/site-packages/matplotlib/pyplot.py", line 1119, in savefig
    res = fig.savefig(*args, **kwargs)  # type: ignore[func-returns-value]
  File "/root/miniconda3/envs/torch2/lib/python3.10/site-packages/matplotlib/figure.py", line 3390, in savefig
    self.canvas.print_figure(fname, **kwargs)
  File "/root/miniconda3/envs/torch2/lib/python3.10/site-packages/matplotlib/backend_bases.py", line 2187, in print_figure
    result = print_method(
  File "/root/miniconda3/envs/torch2/lib/python3.10/site-packages/matplotlib/backend_bases.py", line 2043, in <lambda>
    print_method = functools.wraps(meth)(lambda *args, **kwargs: meth(
  File "/root/miniconda3/envs/torch2/lib/python3.10/site-packages/matplotlib/backends/backend_agg.py", line 497, in print_png
    self._print_pil(filename_or_obj, "png", pil_kwargs, metadata)
  File "/root/miniconda3/envs/torch2/lib/python3.10/site-packages/matplotlib/backends/backend_agg.py", line 446, in _print_pil
    mpl.image.imsave(
  File "/root/miniconda3/envs/torch2/lib/python3.10/site-packages/matplotlib/image.py", line 1656, in imsave
    image.save(fname, **pil_kwargs)
  File "/root/miniconda3/envs/torch2/lib/python3.10/site-packages/PIL/Image.py", line 2410, in save
    fp = builtins.open(filename, "w+b")
FileNotFoundError: [Errno 2] No such file or directory: './pic/type1_loss.png'
Traceback (most recent call last):
  File "/lihao/2023_AAI_Project_Unsteable_hand_writing_-Digit-Recognitionle/src/main.py", line 4, in <module>
    from dataset import HandwrittenDigitsDataset
  File "/lihao/2023_AAI_Project_Unsteable_hand_writing_-Digit-Recognitionle/src/dataset.py", line 1, in <module>
    import numpy as np
ModuleNotFoundError: No module named 'numpy'
